Workbook
Name _______bot1: #REF!
Name _______bot3: #REF!
Name _______bot4: #REF!
Name _______bot5: #REF!
Name _______bot6: #REF!
Name _______top1: #REF!
Name _______top2: #REF!
Name _______top3: #REF!
Name _______top4: #REF!
Name _______top5: #REF!
Name _______top6: #REF!
Name ______bot2: #REF!
Name _____bot1: #REF!
Name _____bot3: #REF!
Name _____bot4: #REF!
Name _____bot5: #REF!
Name _____bot6: #REF!
Name _____top1: #REF!
Name _____top2: #REF!
Name _____top3: #REF!
Name _____top4: #REF!
Name _____top5: #REF!
Name _____top6: #REF!
Name ____bot1: #REF!
Name ____bot2: #REF!
Name ____bot3: #REF!
Name ____bot4: #REF!
Name ____bot5: #REF!
Name ____bot6: #REF!
Name ____top1: #REF!
Name ____top2: #REF!
Name ____top3: #REF!
Name ____top4: #REF!
Name ____top5: #REF!
Name ____top6: #REF!
Name ___bot1: #REF!
Name ___bot2: #REF!
Name ___bot3: #REF!
Name ___bot4: #REF!
Name ___bot5: #REF!
Name ___bot6: #REF!
Name ___top1: #REF!
Name ___top2: #REF!
Name ___top3: #REF!
Name ___top4: #REF!
Name ___top5: #REF!
Name ___top6: #REF!
Name __bot1: #REF!
Name __bot2: #REF!
Name __bot3: #REF!
Name __bot4: #REF!
Name __bot5: #REF!
Name __bot6: #REF!
Name __top1: #REF!
Name __top2: #REF!
Name __top3: #REF!
Name __top4: #REF!
Name __top5: #REF!
Name __top6: #REF!
Name _bot1: #REF!

Sheet How to update
B2: How to update
B3: 1. | C3: Navigate to the tabs included in the 'Data Links' tab at the bottom of this spreadsheet
B4: 2. | C4: Starting with the first link, download the data and open the downloaded spreadsheet
B5: 3. | C5: In the downloaded spreadsheet, find the tab that contains the same data as the tab in this spreadsheet that you are trying to update and copy all of the data and only the data
B6: 4. | C6: Line the first month of the copied data up with the first month in the tab you are hoping to update and paste the new data on top of it, overwriting the old data (i.e. July 2014 should be pasted on top of July 2014)
B7: 5. | C7: Repeat for all tabs until the spreadsheet is completely updated
B8: 6. | C8: Do a quick comparison with the ONS published stats to make sure all the formulas are pulling through correctly
B9: 7. | C9: To update the dashboard, ensure the yellow date box in the top left hand corner of the dashboard tab is set to the correct value

Sheet Data links
B2: Tab | C2: Data link (August - Make sure to download most recent month!!!)
B3: 1. Payrolled employees | C3: https://www.ons.gov.uk/employmentandlabourmarket/peopleinwork/earningsandworkinghours/datasets/realtimeinformationstatisticsreferencetableseasonallyadjusted
B4: 23. Employees Industry
B5: 2, 5, 10, 11, 13, 15, 18, 20, 21 | C5: A01: Summary of labour market statistics - Office for National Statistics
B6: 1 UK (Claimant count) | C6: CLA01: Claimant Count - Office for National Statistics
B7: Real Average Weekly Earnings (using CPI) | C7: X09: Real average weekly earnings using consumer price inflation (seasonally adjusted) - Office for National Statistics
B8: Redundancies | C8: HR1: Potential redundancies - Office for National Statistics
B9: Labour market flows | C9: X02: Labour Force Survey flows estimates

Sheet Dashboard
B1: Aug-Oct | L1: Dropdowns: | M1: Month | N1: Offset Count | O1: Year
A2: Year | B2: 2025 | M2: Nov-Jan | N2: 13 | O2: 2022
A3: Offset factor | B3: =((VLOOKUP(B1,$M$2:$N$13, 2, FALSE)-0)+((Dashboard!B2-2024)*12)) | M3: Dec-Feb | N3: =N2+1 | O3: 2023
M4: Jan-Mar | N4: =N3+1 | O4: 2024
B5: {{LFS_PERIOD}} | D5: Current | E5: Change on quarter | F5: Change on the year | G5: Change since Covid-20 | I5: Good or Bad' formatting? | K5: For data showing percentage point change | M5: Feb-Apr | N5: =N4+1 | O5: 2025
B6: Employment (000s) 16+ | D6: {{EMP16_CUR}} | E6: {{EMP16_DQ}} | F6: {{EMP16_DY}} | G6: {{EMP16_DC}} | I6: Minus = Bad | M6: Mar-May | N6: =N5+1 | O6: 2026
B7: Employment rate (16-64) | D7: {{EMP_RT_CUR}} | E7: {{EMP_RT_DQ}} | F7: {{EMP_RT_DY}} | G7: {{EMP_RT_DC}} | I7: Minus = Bad | K7: Add 'pp' in brief | M7: Apr-Jun | N7: =N6+1 | O7: 2027
B8: Unemployment, 16+ (000s) | D8: {{UNEMP16_CUR}} | E8: {{UNEMP16_DQ}} | F8: {{UNEMP16_DY}} | G8: {{UNEMP16_DC}} | I8: Minus = Good | M8: May-Jul | N8: =N7+1 | O8: 2028
B9: Unemployment rate, 16+ | D9: {{UNEMP_RT_CUR}} | E9: {{UNEMP_RT_DQ}} | F9: {{UNEMP_RT_DY}} | G9: {{UNEMP_RT_DC}} | I9: Minus = Good | K9: Add 'pp' in brief | M9: Jun-Aug | N9: =N8+1 | O9: 2029
B10: Economic inactivity (000s) (16-64) | D10: {{INACT_CUR}} | E10: {{INACT_DQ}} | F10: {{INACT_DY}} | G10: {{INACT_DC}} | I10: Minus = Good | M10: Jul-Sep | N10: =N9+1 | O10: 2030
B11: Economic inactivity rate (16-64) | D11: {{INACT_RT_CUR}} | E11: {{INACT_RT_DQ}} | F11: {{INACT_RT_DY}} | G11: {{INACT_RT_DC}} | I11: Minus = Good | K11: Add 'pp' in brief | M11: Aug-Oct | N11: =N10+1
B12: 50-64s inactivity (000s) | D12: {{INACT5064_CUR}} | E12: {{INACT5064_DQ}} | F12: {{INACT5064_DY}} | G12: {{INACT5064_DC}} | I12: Minus = Good | M12: Sep-Nov | N12: =N11+1
B13: 50-64s inactivity rate | D13: {{INACT5064_RT_CUR}} | E13: {{INACT5064_RT_DQ}} | F13: {{INACT5064_RT_DY}} | G13: {{INACT5064_RT_DC}} | I13: Minus = Good | K13: Add 'pp' in brief | M13: Oct-Dec | N13: =N12+1
B14: Provisional December 2024 HMRC Payroll employees (000s) | D14: {{PAYROLL_CUR}} | E14: {{PAYROLL_DQ}} | F14: {{PAYROLL_DY}} | G14: {{PAYROLL_DC}} | I14: Minus = Bad
A15: *note: covid period is different (Jan-Mar) due to reporting periods | B15: Provisional Nov 2024-Jan 2025 Vacancies (000s) | D15: {{VAC_CUR}} | E15: {{VAC_DQ}} | F15: {{VAC_DY}} | G15: {{VAC_DC}} | I15: Do not format
B16: Wage growth in cash terms (total pay, including bonuses, yearly % change) | C16: Change in annual earnings | D16: {{WAGES_CUR}} | E16: {{WAGES_DQ}} | F16: {{WAGES_DY}} | G16: {{WAGES_DC}} | I16: Minus = Bad
B17: Wage growth adjusted for inflation (total pay, including bonuses, yearly % change) | D17: {{WAGES_CPI_CUR}} | E17: {{WAGES_CPI_DQ}} | F17: {{WAGES_CPI_DY}} | G17: {{WAGES_CPI_DC}} | I17: Minus = Bad

Sheet 1. Payrolled employees (UK)
B1: Current | C1: Change on month (singular) | D1: Change on quarter | E1: Change year on year | F1: Change since Covid-19 | G1: Change since 2024 election | H1: Change since coming into office | I1: Change since start of the year | J1: Max
A2: Number | B2: {{PAYROLL_CUR}} | C2: {=INDEX($B$11:$B$1048576,COUNTA($B$11:$B$1048576))-INDEX($B$11:$B$1048576,COUNTA($B$11:$B$1048576)-1)} | D2: {{PAYROLL_DQ}} | E2: {{PAYROLL_DY}} | F2: {{PAYROLL_DC}} | G2: {{PAYROLL_DE}} | H2: {=INDEX($B$11:$B$1048576,COUNTA($B$11:$B$1048576))-$B$130} | I2: {=INDEX(B$11:B$1048576,COUNTA(B$11:B$1048576))-_xlfn.XLOOKUP("January " & TEXT(TODAY(),"yyyy"),A$11:A$1048576,B$11:B$1048576)} | J2: =MAX($B$11:$B$1048576)
A3: % | C3: {=INDEX($B$11:$B$1048576,COUNTA($B$11:$B$1048576))/INDEX($B$11:$B$1048576,COUNTA($B$11:$B$1048576)-1)-1} | D3: =AVERAGE(OFFSET(INDEX($B$11:$B$1048576,COUNTA($B$11:$B$1048576)),-2,0,3,1))/AVERAGE(OFFSET(INDEX($B$11:$B$1048576,COUNTA($B$11:$B$1048576)),-5,0,3,1))-1 | E3: =AVERAGE(OFFSET(INDEX($B$11:$B$1048576,COUNTA($B$11:$B$1048576)),-2,0,3,1))/AVERAGE(OFFSET(INDEX($B$11:$B$1048576,COUNTA($B$11:$B$1048576)),-14,0,3,1))-1 | F3: {=INDEX($B$11:$B$1048576,COUNTA($B$11:$B$1048576))/AVERAGE($B$76:$B$78)-1} | G3: =AVERAGE(OFFSET(INDEX($B$11:$B$1048576,COUNTA($B$11:$B$1048576)),-2,0,3,1))/AVERAGE($B$128:$B$130)-1 | H3: {=INDEX($B$11:$B$1048576,COUNTA($B$11:$B$1048576))/$B$130-1} | I3: {=INDEX(B$11:B$1048576,COUNTA(B$11:B$1048576))/_xlfn.XLOOKUP("January " & TEXT(TODAY(),"yyyy"),A$11:A$1048576,B$11:B$1048576)-1}
A5: 1. Payrolled employee counts from PAYE RTI
A6: UK, all industries, seasonally adjusted
A8: Units | B8: Payrolled employees
A10: Date | B10: Payrolled employees | C10: Change on previous month

Sheet 23. Employees Industry
A1: Yearly change | B1: Agriculture, forestry and fishing | C1: Mining and quarrying | D1: Manufacturing | E1: Energy production and supply | F1: Water supply, sewerage and waste | G1: Construction | H1: Wholesale and retail; repair of motor vehicles | I1: Transportation and storage | J1: Accommodation and food service activities | K1: Information and communication | L1: Finance and insurance | M1: Real estate | N1: Professional, scientific and technical | O1: Administrative and support services | P1: Public administration and defence; social security | Q1: Education | R1: Health and social work | S1: Arts, entertainment and recreation | T1: Other service activities | U1: Households and Extraterritorial | V1: UK
A2: Number | B2: {=INDEX(B$12:B$1048576,COUNTA(B$12:B$1048576))-INDEX(B$12:B$1048576,COUNTA(B$12:B$1048576)-12)} | C2: {=INDEX(C$12:C$1048576,COUNTA(C$12:C$1048576))-INDEX(C$12:C$1048576,COUNTA(C$12:C$1048576)-12)} | D2: {=INDEX(D$12:D$1048576,COUNTA(D$12:D$1048576))-INDEX(D$12:D$1048576,COUNTA(D$12:D$1048576)-12)} | E2: {=INDEX(E$12:E$1048576,COUNTA(E$12:E$1048576))-INDEX(E$12:E$1048576,COUNTA(E$12:E$1048576)-12)} | F2: {=INDEX(F$12:F$1048576,COUNTA(F$12:F$1048576))-INDEX(F$12:F$1048576,COUNTA(F$12:F$1048576)-12)} | G2: {=INDEX(G$12:G$1048576,COUNTA(G$12:G$1048576))-INDEX(G$12:G$1048576,COUNTA(G$12:G$1048576)-12)} | H2: {=INDEX(H$12:H$1048576,COUNTA(H$12:H$1048576))-INDEX(H$12:H$1048576,COUNTA(H$12:H$1048576)-12)} | I2: {=INDEX(I$12:I$1048576,COUNTA(I$12:I$1048576))-INDEX(I$12:I$1048576,COUNTA(I$12:I$1048576)-12)} | ... V2: {=INDEX(V$12:V$1048576,COUNTA(V$12:V$1048576))-INDEX(V$12:V$1048576,COUNTA(V$12:V$1048576)-12)}
A3: % | B3: {=INDEX(B$12:B$1048576,COUNTA(B$12:B$1048576))/INDEX(B$12:B$1048576,COUNTA(B$12:B$1048576)-12)-1} | C3: {=INDEX(C$12:C$1048576,COUNTA(C$12:C$1048576))/INDEX(C$12:C$1048576,COUNTA(C$12:C$1048576)-12)-1} | D3: {=INDEX(D$12:D$1048576,COUNTA(D$12:D$1048576))/INDEX(D$12:D$1048576,COUNTA(D$12:D$1048576)-12)-1} | E3: {=INDEX(E$12:E$1048576,COUNTA(E$12:E$1048576))/INDEX(E$12:E$1048576,COUNTA(E$12:E$1048576)-12)-1} | F3: {=INDEX(F$12:F$1048576,COUNTA(F$12:F$1048576))/INDEX(F$12:F$1048576,COUNTA(F$12:F$1048576)-12)-1} | G3: {=INDEX(G$12:G$1048576,COUNTA(G$12:G$1048576))/INDEX(G$12:G$1048576,COUNTA(G$12:G$1048576)-12)-1} | H3: {=INDEX(H$12:H$1048576,COUNTA(H$12:H$1048576))/INDEX(H$12:H$1048576,COUNTA(H$12:H$1048576)-12)-1} | I3: {=INDEX(I$12:I$1048576,COUNTA(I$12:I$1048576))/INDEX(I$12:I$1048576,COUNTA(I$12:I$1048576)-12)-1} | ... V3: {=INDEX(V$12:V$1048576,COUNTA(V$12:V$1048576))/INDEX(V$12:V$1048576,COUNTA(V$12:V$1048576)-12)-1}
A4: Rank | B4: =RANK(B2,$B$2:$U$2) | C4: =RANK(C2,$B$2:$U$2) | D4: =RANK(D2,$B$2:$U$2) | E4: =RANK(E2,$B$2:$U$2) | F4: =RANK(F2,$B$2:$U$2) | G4: =RANK(G2,$B$2:$U$2) | H4: =RANK(H2,$B$2:$U$2) | I4: =RANK(I2,$B$2:$U$2) | ... U4: =RANK(U2,$B$2:$U$2)
A5: 23. Payrolled employees from PAYE RTI
A6: UK, seasonally adjusted
A7: Earnings and employment from Pay As You Earn Real Time Information, seasonally adjusted - Office for National Statistics
A8: Units | B8: Payrolled employees
B10: A | C10: B | D10: C | E10: D | F10: E | G10: F | H10: G | I10: H | J10: I | K10: J | L10: K | M10: L | N10: M | O10: N | P10: O | Q10: P | R10: Q | S10: R | T10: S | U10: T-U
A11: Date | B11: Agriculture, forestry and fishing | C11: Mining and quarrying | D11: Manufacturing | E11: Energy production and supply | F11: Water supply, sewerage and waste | G11: Construction | H11: Wholesale and retail; repair of motor vehicles | I11: Transportation and storage | J11: Accommodation and food service activities | K11: Information and communication | L11: Finance and insurance | M11: Real estate | N11: Professional, scientific and technical | O11: Administrative and support services | P11: Public administration and defence; social security | Q11: Education | R11: Health and social work | S11: Arts, entertainment and recreation | T11: Other service activities | U11: Households and Extraterritorial | V11: UK
A12: July 2014 | B12: 177905 | C12: 58307 | D12: 2336087 | E12: 92943 | F12: 155653 | G12: 1081408 | H12: 4255533 | I12: 1164523 | J12: 1758770 | K12: 1060896 | L12: 1054685 | M12: 401247 | N12: 1934869 | O12: 2230040 | P12: 1588018 | Q12: 2879249 | R12: 3429105 | S12: 520128 | T12: 486204 | U12: 96542 | V12: 26762113
A13: August 2014 | B13: 178179 | C13: 58487 | D13: 2340535 | E13: 92980 | F13: 155943 | G13: 1087984 | H13: 4264797 | I13: 1165997 | J13: 1767010 | K13: 1066653 | L13: 1055820 | M13: 401904 | N13: 1943596 | O13: 2250253 | P13: 1584818 | Q13: 2881488 | R13: 3435643 | S13: 521066 | T13: 487131 | U13: 96940 | V13: 26837223

Sheet 2
B2: Aged 16 and over | J2: Aged 16-64 | R2: Aged 16-17 | Z2: Aged 18-24 | AH2: Aged 25-34 | AP2: Aged 35-49 | AX2: Aged 50-64 | BF2: Age 65+
B3: Employment | D3: Unemployment | F3: Activity | H3: Inactivity | J3: Employment | L3: Unemployment | N3: Activity | P3: Inactivity | R3: Employment | T3: Unemployment | V3: Activity | X3: Inactivity | Z3: Employment | AB3: Unemployment | AD3: Activity | AF3: Inactivity | AH3: Employment | AJ3: Unemployment | AL3: Activity | AN3: Inactivity | AP3: Employment | AR3: Unemployment | AT3: Activity | AV3: Inactivity | AX3: Employment | AZ3: Unemployment | BB3: Activity | BD3: Inactivity | BF3: Employment | BH3: Unemployment | BJ3: Activity | BL3: Inactivity
B4: level | C4: rate (%) | D4: level | E4: rate (%) | F4: level | G4: rate (%) | H4: level | I4: rate (%) | J4: level | K4: rate (%) | L4: level | M4: rate (%) | N4: level | O4: rate (%) | P4: level | Q4: rate (%) | R4: level | S4: rate (%) | T4: level | U4: rate (%) | V4: level | W4: rate (%) | X4: level | Y4: rate (%) | Z4: level | AA4: rate (%) | AB4: level | AC4: rate (%) | AD4: level | AE4: rate (%) | AF4: level | AG4: rate (%) | AH4: level | AI4: rate (%) | AJ4: level | AK4: rate (%) | AL4: level | AM4: rate (%) | AN4: level | AO4: rate (%) | AP4: level | AQ4: rate (%) | AR4: level | AS4: rate (%) | AT4: level | AU4: rate (%) | AV4: level | AW4: rate (%) | AX4: level | AY4: rate (%) | AZ4: level | BA4: rate (%) | BB4: level | BC4: rate (%) | BD4: level | BE4: rate (%) | BF4: level | BG4: rate (%) | BH4: level | BI4: rate (%) | BJ4: level | BK4: rate (%) | BL4: level | BM4: rate (%)
A5: Current | B5: {{EMP16_CUR}} | C5: {{EMP_RT_CUR}} | D5: {{UNEMP16_CUR}} | E5: {{UNEMP_RT_CUR}} | F5: {=INDEX(F$18:F$1048576,COUNTA(F$18:F$1048576))} | G5: {=INDEX(G$18:G$1048576,COUNTA(G$18:G$1048576))} | H5: {{INACT_CUR}} | I5: {{INACT_RT_CUR}} | J5: {=INDEX(J$18:J$1048576,COUNTA(J$18:J$1048576))} | K5: {=INDEX(K$18:K$1048576,COUNTA(K$18:K$1048576))} | L5: {=INDEX(L$18:L$1048576,COUNTA(L$18:L$1048576))} | M5: {=INDEX(M$18:M$1048576,COUNTA(M$18:M$1048576))} | N5: {=INDEX(N$18:N$1048576,COUNTA(N$18:N$1048576))} | O5: {=INDEX(O$18:O$1048576,COUNTA(O$18:O$1048576))} | P5: {=INDEX(P$18:P$1048576,COUNTA(P$18:P$1048576))} | Q5: {=INDEX(Q$18:Q$1048576,COUNTA(Q$18:Q$1048576))} | ... BM5: {=INDEX(BM$18:BM$1048576,COUNTA(BM$18:BM$1048576))}
A6: Quarterly change | B6: {{EMP16_DQ}} | C6: {{EMP_RT_DQ}} | D6: {{UNEMP16_DQ}} | E6: {{UNEMP_RT_DQ}} | F6: {=INDEX(F$18:F$1048576,COUNTA(F$18:F$1048576))-INDEX(F$18:F$1048576,COUNTA(F$18:F$1048576)-3)} | G6: {=INDEX(G$18:G$1048576,COUNTA(G$18:G$1048576))-INDEX(G$18:G$1048576,COUNTA(G$18:G$1048576)-3)} | H6: {{INACT_DQ}} | I6: {{INACT_RT_DQ}} | J6: {=INDEX(J$18:J$1048576,COUNTA(J$18:J$1048576))-INDEX(J$18:J$1048576,COUNTA(J$18:J$1048576)-3)} | K6: {=INDEX(K$18:K$1048576,COUNTA(K$18:K$1048576))-INDEX(K$18:K$1048576,COUNTA(K$18:K$1048576)-3)} | L6: {=INDEX(L$18:L$1048576,COUNTA(L$18:L$1048576))-INDEX(L$18:L$1048576,COUNTA(L$18:L$1048576)-3)} | M6: {=INDEX(M$18:M$1048576,COUNTA(M$18:M$1048576))-INDEX(M$18:M$1048576,COUNTA(M$18:M$1048576)-3)} | N6: {=INDEX(N$18:N$1048576,COUNTA(N$18:N$1048576))-INDEX(N$18:N$1048576,COUNTA(N$18:N$1048576)-3)} | O6: {=INDEX(O$18:O$1048576,COUNTA(O$18:O$1048576))-INDEX(O$18:O$1048576,COUNTA(O$18:O$1048576)-3)} | P6: {=INDEX(P$18:P$1048576,COUNTA(P$18:P$1048576))-INDEX(P$18:P$1048576,COUNTA(P$18:P$1048576)-3)} | Q6: {=INDEX(Q$18:Q$1048576,COUNTA(Q$18:Q$1048576))-INDEX(Q$18:Q$1048576,COUNTA(Q$18:Q$1048576)-3)} | ... BM6: {=INDEX(BM$18:BM$1048576,COUNTA(BM$18:BM$1048576))-INDEX(BM$18:BM$1048576,COUNTA(BM$18:BM$1048576)-3)}
A7: Change year on year | B7: {{EMP16_DY}} | C7: {{EMP_RT_DY}} | D7: {{UNEMP16_DY}} | E7: {{UNEMP_RT_DY}} | F7: {=INDEX(F$18:F$1048576,COUNTA(F$18:F$1048576))-INDEX(F$18:F$1048576,COUNTA(F$18:F$1048576)-12)} | G7: {=INDEX(G$18:G$1048576,COUNTA(G$18:G$1048576))-INDEX(G$18:G$1048576,COUNTA(G$18:G$1048576)-12)} | H7: {{INACT_DY}} | I7: {{INACT_RT_DY}} | J7: {=INDEX(J$18:J$1048576,COUNTA(J$18:J$1048576))-INDEX(J$18:J$1048576,COUNTA(J$18:J$1048576)-12)} | K7: {=INDEX(K$18:K$1048576,COUNTA(K$18:K$1048576))-INDEX(K$18:K$1048576,COUNTA(K$18:K$1048576)-12)} | L7: {=INDEX(L$18:L$1048576,COUNTA(L$18:L$1048576))-INDEX(L$18:L$1048576,COUNTA(L$18:L$1048576)-12)} | M7: {=INDEX(M$18:M$1048576,COUNTA(M$18:M$1048576))-INDEX(M$18:M$1048576,COUNTA(M$18:M$1048576)-12)} | N7: {=INDEX(N$18:N$1048576,COUNTA(N$18:N$1048576))-INDEX(N$18:N$1048576,COUNTA(N$18:N$1048576)-12)} | O7: {=INDEX(O$18:O$1048576,COUNTA(O$18:O$1048576))-INDEX(O$18:O$1048576,COUNTA(O$18:O$1048576)-12)} | P7: {=INDEX(P$18:P$1048576,COUNTA(P$18:P$1048576))-INDEX(P$18:P$1048576,COUNTA(P$18:P$1048576)-12)} | Q7: {=INDEX(Q$18:Q$1048576,COUNTA(Q$18:Q$1048576))-INDEX(Q$18:Q$1048576,COUNTA(Q$18:Q$1048576)-12)} | ... BM7: {=INDEX(BM$18:BM$1048576,COUNTA(BM$18:BM$1048576))-INDEX(BM$18:BM$1048576,COUNTA(BM$18:BM$1048576)-12)}
A8: Change since Covid (Dec 19-feb 20) | B8: {{EMP16_DC}} | C8: {{EMP_RT_DC}} | D8: {{UNEMP16_DC}} | E8: {{UNEMP_RT_DC}} | F8: {=INDEX(F$18:F$1048576,COUNTA(F$18:F$1048576))-F$351} | G8: {=INDEX(G$18:G$1048576,COUNTA(G$18:G$1048576))-G$351} | H8: {{INACT_DC}} | I8: {{INACT_RT_DC}} | J8: {=INDEX(J$18:J$1048576,COUNTA(J$18:J$1048576))-J$351} | K8: {=INDEX(K$18:K$1048576,COUNTA(K$18:K$1048576))-K$351} | L8: {=INDEX(L$18:L$1048576,COUNTA(L$18:L$1048576))-L$351} | M8: {=INDEX(M$18:M$1048576,COUNTA(M$18:M$1048576))-M$351} | N8: {=INDEX(N$18:N$1048576,COUNTA(N$18:N$1048576))-N$351} | O8: {=INDEX(O$18:O$1048576,COUNTA(O$18:O$1048576))-O$351} | P8: {=INDEX(P$18:P$1048576,COUNTA(P$18:P$1048576))-P$351} | Q8: {=INDEX(Q$18:Q$1048576,COUNTA(Q$18:Q$1048576))-Q$351} | ... BM8: {=INDEX(BM$18:BM$1048576,COUNTA(BM$18:BM$1048576))-BM$351}
A9: change since 2010 election | B9: {=INDEX(B$18:B$1048576,COUNTA(B$18:B$1048576))-B$233} | C9: {=INDEX(C$18:C$1048576,COUNTA(C$18:C$1048576))-C$233} | D9: {=INDEX(D$18:D$1048576,COUNTA(D$18:D$1048576))-D$233} | E9: {=INDEX(E$18:E$1048576,COUNTA(E$18:E$1048576))-E$233} | F9: {=INDEX(F$18:F$1048576,COUNTA(F$18:F$1048576))-F$233} | G9: {=INDEX(G$18:G$1048576,COUNTA(G$18:G$1048576))-G$233} | H9: {=INDEX(H$18:H$1048576,COUNTA(H$18:H$1048576))-H$233} | I9: {=INDEX(I$18:I$1048576,COUNTA(I$18:I$1048576))-I$233} | ... BM9: {=INDEX(BM$18:BM$1048576,COUNTA(BM$18:BM$1048576))-BM$233}
A10: change since 2024 election | B10: {{EMP16_DE}} | C10: {{EMP_RT_DE}} | D10: {{UNEMP16_DE}} | E10: {{UNEMP_RT_DE}} | F10: {=INDEX(F$18:F$1048576,COUNTA(F$18:F$1048576))-F$403} | G10: {=INDEX(G$18:G$1048576,COUNTA(G$18:G$1048576))-G$403} | H10: {{INACT_DE}} | I10: {{INACT_RT_DE}} | J10: {=INDEX(J$18:J$1048576,COUNTA(J$18:J$1048576))-J$403} | K10: {=INDEX(K$18:K$1048576,COUNTA(K$18:K$1048576))-K$403} | L10: {=INDEX(L$18:L$1048576,COUNTA(L$18:L$1048576))-L$403} | M10: {=INDEX(M$18:M$1048576,COUNTA(M$18:M$1048576))-M$403} | N10: {=INDEX(N$18:N$1048576,COUNTA(N$18:N$1048576))-N$403} | O10: {=INDEX(O$18:O$1048576,COUNTA(O$18:O$1048576))-O$403} | P10: {=INDEX(P$18:P$1048576,COUNTA(P$18:P$1048576))-P$403} | Q10: {=INDEX(Q$18:Q$1048576,COUNTA(Q$18:Q$1048576))-Q$403} | ... BM10: {=INDEX(BM$18:BM$1048576,COUNTA(BM$18:BM$1048576))-BM$403}
A11: Table 2: Labour market activity by age group (seasonally adjusted) | J11: =J418-J402
A12: Date of publication: | B12: 45335 | G12: Date of next publication: | J12: 45363 | M12: Source: Labour Force Survey
A13: Inquiries: Email: | B13: labour.market@ons.gov.uk | G13: Tel: 01633 455400 | J13: =K414-K417
A14: United Kingdom (thousands) seasonally adjusted
B15: Aged 16 and over | J15: Aged 16-64 | R15: Aged 16-17 | Z15: Aged 18-24 | AH15: Aged 25-34 | AP15: Aged 35-49 | AX15: Aged 50-64 | BF15: Age 65+
B16: Employment | D16: Unemployment | F16: Activity | H16: Inactivity | J16: Employment | L16: Unemployment | N16: Activity | P16: Inactivity | R16: Employment | T16: Unemployment | V16: Activity | X16: Inactivity | Z16: Employment | AB16: Unemployment | AD16: Activity | AF16: Inactivity | AH16: Employment | AJ16: Unemployment | AL16: Activity | AN16: Inactivity | AP16: Employment | AR16: Unemployment | AT16: Activity | AV16: Inactivity | AX16: Employment | AZ16: Unemployment | BB16: Activity | BD16: Inactivity | BF16: Employment | BH16: Unemployment | BJ16: Activity | BL16: Inactivity
B17: level | C17: rate (%) | D17: level | E17: rate (%) | F17: level | G17: rate (%) | H17: level | I17: rate (%) | J17: level | K17: rate (%) | L17: level | M17: rate (%) | N17: level | O17: rate (%) | P17: level | Q17: rate (%) | R17: level | S17: rate (%) | T17: level | U17: rate (%) | V17: level | W17: rate (%) | X17: level | Y17: rate (%) | Z17: level | AA17: rate (%) | AB17: level | AC17: rate (%) | AD17: level | AE17: rate (%) | AF17: level | AG17: rate (%) | AH17: level | AI17: rate (%) | AJ17: level | AK17: rate (%) | AL17: level | AM17: rate (%) | AN17: level | AO17: rate (%) | AP17: level | AQ17: rate (%) | AR17: level | AS17: rate (%) | AT17: level | AU17: rate (%) | AV17: level | AW17: rate (%) | AX17: level | AY17: rate (%) | AZ17: level | BA17: rate (%) | BB17: level | BC17: rate (%) | BD17: level | BE17: rate (%) | BF17: level | BG17: rate (%) | BH17: level | BI17: rate (%) | BJ17: level | BK17: rate (%) | BL17: level | BM17: rate (%)

Sheet 5
B2: Workforce jobs | C2: Employee jobs | D2: Self-employment jobs | E2: HM Forces | F2: Government- supported trainees
A3: Current | B3: {=INDEX(B$16:B$1048576,COUNTA(B$16:B$1048576))} | C3: {=INDEX(C$16:C$1048576,COUNTA(C$16:C$1048576))} | D3: {=INDEX(D$16:D$1048576,COUNTA(D$16:D$1048576))} | E3: {=INDEX(E$16:E$1048576,COUNTA(E$16:E$1048576))} | F3: {=INDEX(F$16:F$1048576,COUNTA(F$16:F$1048576))}
A4: Quarterly change | B4: {=INDEX(B$16:B$1048576,COUNTA(B$16:B$1048576))-INDEX(B$16:B$1048576,COUNTA(B$16:B$1048576)-1)} | C4: {=INDEX(C$16:C$1048576,COUNTA(C$16:C$1048576))-INDEX(C$16:C$1048576,COUNTA(C$16:C$1048576)-1)} | D4: {=INDEX(D$16:D$1048576,COUNTA(D$16:D$1048576))-INDEX(D$16:D$1048576,COUNTA(D$16:D$1048576)-1)} | E4: {=INDEX(E$16:E$1048576,COUNTA(E$16:E$1048576))-INDEX(E$16:E$1048576,COUNTA(E$16:E$1048576)-1)} | F4: {=INDEX(F$16:F$1048576,COUNTA(F$16:F$1048576))-INDEX(F$16:F$1048576,COUNTA(F$16:F$1048576)-1)}
A5: Max | B5: =MAX(B$16:B$1048576) | C5: =MAX(C$16:C$1048576) | D5: =MAX(D$16:D$1048576) | E5: =MAX(E$16:E$1048576) | F5: =MAX(F$16:F$1048576)
A6: Jobs created since new gov | B6: {=INDEX(B$16:B$1048576,COUNTA(B$16:B$1048576))-B$276} | C6: {=INDEX(C$16:C$1048576,COUNTA(C$16:C$1048576))-C$276} | D6: {=INDEX(D$16:D$1048576,COUNTA(D$16:D$1048576))-D$276} | E6: {=INDEX(E$16:E$1048576,COUNTA(E$16:E$1048576))-E$276} | F6: {=INDEX(F$16:F$1048576,COUNTA(F$16:F$1048576))-F$276}
A8: Table 5: Workforce jobs (seasonally adjusted)1
A9: Date of publication: | C9: 45916 | E9: Date of next publication: | F9: 46007
A10: Inquiries: Email: | C10: workforce.jobs@ons.gov.uk | E10: Telephone: | F10: 01633 455400
F11: Sources: Employer surveys, Labour Force Survey and administrative sources
A12: United Kingdom (thousands) seasonally adjusted
B13: Workforce jobs1 | C13: Employee jobs1 | D13: Self-employment jobs2 | E13: HM Forces | F13: Government- supported trainees2 3
B14: 1 | C14: 2 | D14: 3 | E14: 4 | F14: 5
B15: DYDC | C15: BCAJ | D15: DYZN | E15: LOJX | F15: LOJU

Sheet 10
B1: People | D1: Men | F1: Women
B2: Level1 | C2: Rate per thousand2 | D2: Level1 | E2: Rate per thousand2 | F2: Level1 | G2: Rate per thousand2
A3: Current | B3: {=INDEX(B$18:B$1048576,COUNTA(B$18:B$1048576))} | C3: {=INDEX(C$18:C$1048576,COUNTA(C$18:C$1048576))} | D3: {=INDEX(D$18:D$1048576,COUNTA(D$18:D$1048576))} | E3: {=INDEX(E$18:E$1048576,COUNTA(E$18:E$1048576))} | F3: {=INDEX(F$18:F$1048576,COUNTA(F$18:F$1048576))} | G3: {=INDEX(G$18:G$1048576,COUNTA(G$18:G$1048576))}
A4: Quarterly change | B4: {=INDEX(B$18:B$1048576,COUNTA(B$18:B$1048576))-INDEX(B$18:B$1048576,COUNTA(B$18:B$1048576)-3)} | C4: {=INDEX(C$18:C$1048576,COUNTA(C$18:C$1048576))-INDEX(C$18:C$1048576,COUNTA(C$18:C$1048576)-3)} | D4: {=INDEX(D$18:D$1048576,COUNTA(D$18:D$1048576))-INDEX(D$18:D$1048576,COUNTA(D$18:D$1048576)-3)} | E4: {=INDEX(E$18:E$1048576,COUNTA(E$18:E$1048576))-INDEX(E$18:E$1048576,COUNTA(E$18:E$1048576)-3)} | F4: {=INDEX(F$18:F$1048576,COUNTA(F$18:F$1048576))-INDEX(F$18:F$1048576,COUNTA(F$18:F$1048576)-3)} | G4: {=INDEX(G$18:G$1048576,COUNTA(G$18:G$1048576))-INDEX(G$18:G$1048576,COUNTA(G$18:G$1048576)-3)}
A5: year on year change | B5: {=INDEX(B$18:B$1048576,COUNTA(B$18:B$1048576))-INDEX(B$18:B$1048576,COUNTA(B$18:B$1048576)-12)} | C5: {=INDEX(C$18:C$1048576,COUNTA(C$18:C$1048576))-INDEX(C$18:C$1048576,COUNTA(C$18:C$1048576)-12)} | D5: {=INDEX(D$18:D$1048576,COUNTA(D$18:D$1048576))-INDEX(D$18:D$1048576,COUNTA(D$18:D$1048576)-12)} | E5: {=INDEX(E$18:E$1048576,COUNTA(E$18:E$1048576))-INDEX(E$18:E$1048576,COUNTA(E$18:E$1048576)-12)} | F5: {=INDEX(F$18:F$1048576,COUNTA(F$18:F$1048576))-INDEX(F$18:F$1048576,COUNTA(F$18:F$1048576)-12)} | G5: {=INDEX(G$18:G$1048576,COUNTA(G$18:G$1048576))-INDEX(G$18:G$1048576,COUNTA(G$18:G$1048576)-12)}
A6: Since pandemic | B6: {=INDEX(B$18:B$1048576,COUNTA(B$18:B$1048576))-B$351} | C6: {=INDEX(C$18:C$1048576,COUNTA(C$18:C$1048576))-C$351} | D6: {=INDEX(D$18:D$1048576,COUNTA(D$18:D$1048576))-D$351} | E6: {=INDEX(E$18:E$1048576,COUNTA(E$18:E$1048576))-E$351} | F6: {=INDEX(F$18:F$1048576,COUNTA(F$18:F$1048576))-F$351} | G6: {=INDEX(G$18:G$1048576,COUNTA(G$18:G$1048576))-G$351}
A7: Since 2010 election | B7: {=INDEX(B$18:B$1048576,COUNTA(B$18:B$1048576))-B$233} | C7: {=INDEX(C$18:C$1048576,COUNTA(C$18:C$1048576))-C$233} | D7: {=INDEX(D$18:D$1048576,COUNTA(D$18:D$1048576))-D$233} | E7: {=INDEX(E$18:E$1048576,COUNTA(E$18:E$1048576))-E$233} | F7: {=INDEX(F$18:F$1048576,COUNTA(F$18:F$1048576))-F$233} | G7: {=INDEX(G$18:G$1048576,COUNTA(G$18:G$1048576))-G$233}
A9: Table 10: Redundancies levels1 and rates2 for those aged 16 and over

Sheet 11
C1: Economic inactivity by reason (thousands) | M1: Percentage of economically inactive (%) | W1: Economic inactivity by wants a job (thousands) | AD1: Percentage of economically inactive by wants a job (%) | AK1: Economic inactivity by does not want a job (thousands) | AR1: Percentage of economically inactive by does not want a job (%)
B2: Total economically inactive aged 16-64 (thousands)4 | C2: Student | D2: Looking after family / home | E2: Temp sick | F2: Long-term sick | G2: Discouraged workers1 | H2: Retired | I2: Other2 | J2: Does not want job (thousands) | K2: Wants a job (thousands) | L2: Total economically inactive aged 16-64 | M2: Student | N2: Looking after family / home | O2: Temp sick | P2: Long-term sick | Q2: Discouraged workers1 | R2: Retired | S2: Other2 | T2: Does not want job (%age of economically inactive) | U2: Wants a job (%age of economically inactive) | V2: Total economically inactive wants a job aged 16-64 (thousands) | W2: Student | X2: Looking after family / home | Y2: Temp sick | Z2: Long-term sick | AA2: Discouraged workers1 | AB2: Other2 | AC2: Total wants a job aged 16-64 | AD2: Student | AE2: Looking after family / home | AF2: Temp sick | AG2: Long-term sick | AH2: Discouraged workers1 | AI2: Other2 | AJ2: Total economically inactive does not want a job aged 16-64 (thousands) | AK2: Student | AL2: Looking after family / home | AM2: Temp sick | AN2: Long-term sick | AO2: Retired | AP2: Other2 | AQ2: Total does not want a job aged 16-64 | AR2: Student | AS2: Looking after family / home | AT2: Temp sick | AU2: Long-term sick | AV2: Retired | AW2: Other2
A3: Current | B3: {=INDEX(B$18:B$1048576,COUNTA(B$18:B$1048576))} | C3: {=INDEX(C$30:C$1048576,COUNTA(C$30:C$1048576))} | D3: {=INDEX(D$30:D$1048576,COUNTA(D$30:D$1048576))} | E3: {=INDEX(E$30:E$1048576,COUNTA(E$30:E$1048576))} | F3: {=INDEX(F$30:F$1048576,COUNTA(F$30:F$1048576))} | G3: {=INDEX(G$30:G$1048576,COUNTA(G$30:G$1048576))} | H3: {=INDEX(H$30:H$1048576,COUNTA(H$30:H$1048576))} | I3: {=INDEX(I$30:I$1048576,COUNTA(I$30:I$1048576))} | J3: {=INDEX(J$30:J$1048576,COUNTA(J$30:J$1048576))} | K3: {=INDEX(K$30:K$1048576,COUNTA(K$30:K$1048576))} | L3: {=INDEX(L$18:L$1048576,COUNTA(L$18:L$1048576))} | M3: {=INDEX(M$30:M$1048576,COUNTA(M$30:M$1048576))} | N3: {=INDEX(N$30:N$1048576,COUNTA(N$30:N$1048576))} | O3: {=INDEX(O$30:O$1048576,COUNTA(O$30:O$1048576))} | P3: {=INDEX(P$30:P$1048576,COUNTA(P$30:P$1048576))} | Q3: {=INDEX(Q$30:Q$1048576,COUNTA(Q$30:Q$1048576))} | R3: {=INDEX(R$30:R$1048576,COUNTA(R$30:R$1048576))} | S3: {=INDEX(S$30:S$1048576,COUNTA(S$30:S$1048576))} | T3: {=INDEX(T$30:T$1048576,COUNTA(T$30:T$1048576))} | U3: {=INDEX(U$30:U$1048576,COUNTA(U$30:U$1048576))} | V3: {=INDEX(V$18:V$1048576,COUNTA(V$18:V$1048576))} | W3: {=INDEX(W$18:W$1048576,COUNTA(W$18:W$1048576))} | X3: {=INDEX(X$18:X$1048576,COUNTA(X$18:X$1048576))} | Y3: {=INDEX(Y$18:Y$1048576,COUNTA(Y$18:Y$1048576))} | Z3: {=INDEX(Z$18:Z$1048576,COUNTA(Z$18:Z$1048576))} | AA3: {=INDEX(AA$18:AA$1048576,COUNTA(AA$18:AA$1048576))} | AB3: {=INDEX(AB$18:AB$1048576,COUNTA(AB$18:AB$1048576))} | AC3: {=INDEX(AC$18:AC$1048576,COUNTA(AC$18:AC$1048576))} | ... AW3: {=INDEX(AW$18:AW$1048576,COUNTA(AW$18:AW$1048576))}
A4: Quarterly change | B4: {=INDEX(B$18:B$1048576,COUNTA(B$18:B$1048576))-INDEX(B$18:B$1048576,COUNTA(B$18:B$1048576)-3)} | C4: {=INDEX(C$18:C$1048576,COUNTA(C$18:C$1048576))-INDEX(C$18:C$1048576,COUNTA(C$18:C$1048576)-3)} | D4: {=INDEX(D$18:D$1048576,COUNTA(D$18:D$1048576))-INDEX(D$18:D$1048576,COUNTA(D$18:D$1048576)-3)} | E4: {=INDEX(E$18:E$1048576,COUNTA(E$18:E$1048576))-INDEX(E$18:E$1048576,COUNTA(E$18:E$1048576)-3)} | F4: {=INDEX(F$18:F$1048576,COUNTA(F$18:F$1048576))-INDEX(F$18:F$1048576,COUNTA(F$18:F$1048576)-3)} | G4: {=INDEX(G$18:G$1048576,COUNTA(G$18:G$1048576))-INDEX(G$18:G$1048576,COUNTA(G$18:G$1048576)-3)} | H4: {=INDEX(H$18:H$1048576,COUNTA(H$18:H$1048576))-INDEX(H$18:H$1048576,COUNTA(H$18:H$1048576)-3)} | I4: {=INDEX(I$18:I$1048576,COUNTA(I$18:I$1048576))-INDEX(I$18:I$1048576,COUNTA(I$18:I$1048576)-3)} | ... AW4: {=INDEX(AW$18:AW$1048576,COUNTA(AW$18:AW$1048576))-INDEX(AW$18:AW$1048576,COUNTA(AW$18:AW$1048576)-3)}
A5: year on year change | B5: {=INDEX(B$18:B$1048576,COUNTA(B$18:B$1048576))-INDEX(B$18:B$1048576,COUNTA(B$18:B$1048576)-12)} | C5: {=INDEX(C$18:C$1048576,COUNTA(C$18:C$1048576))-INDEX(C$18:C$1048576,COUNTA(C$18:C$1048576)-12)} | D5: {=INDEX(D$18:D$1048576,COUNTA(D$18:D$1048576))-INDEX(D$18:D$1048576,COUNTA(D$18:D$1048576)-12)} | E5: {=INDEX(E$18:E$1048576,COUNTA(E$18:E$1048576))-INDEX(E$18:E$1048576,COUNTA(E$18:E$1048576)-12)} | F5: {=INDEX(F$18:F$1048576,COUNTA(F$18:F$1048576))-INDEX(F$18:F$1048576,COUNTA(F$18:F$1048576)-12)} | G5: {=INDEX(G$18:G$1048576,COUNTA(G$18:G$1048576))-INDEX(G$18:G$1048576,COUNTA(G$18:G$1048576)-12)} | H5: {=INDEX(H$18:H$1048576,COUNTA(H$18:H$1048576))-INDEX(H$18:H$1048576,COUNTA(H$18:H$1048576)-12)} | I5: {=INDEX(I$18:I$1048576,COUNTA(I$18:I$1048576))-INDEX(I$18:I$1048576,COUNTA(I$18:I$1048576)-12)} | ... AW5: {=INDEX(AW$18:AW$1048576,COUNTA(AW$18:AW$1048576))-INDEX(AW$18:AW$1048576,COUNTA(AW$18:AW$1048576)-12)}
A6: Since pandemic | B6: {=INDEX(B$18:B$1048576,COUNTA(B$18:B$1048576))-B$351} | C6: {=INDEX(C$18:C$1048576,COUNTA(C$18:C$1048576))-C$351} | D6: {=INDEX(D$18:D$1048576,COUNTA(D$18:D$1048576))-D$351} | E6: {=INDEX(E$18:E$1048576,COUNTA(E$18:E$1048576))-E$351} | F6: {=INDEX(F$18:F$1048576,COUNTA(F$18:F$1048576))-F$351} | G6: {=INDEX(G$18:G$1048576,COUNTA(G$18:G$1048576))-G$351} | H6: {=INDEX(H$18:H$1048576,COUNTA(H$18:H$1048576))-H$351} | I6: {=INDEX(I$18:I$1048576,COUNTA(I$18:I$1048576))-I$351} | ... AW6: {=INDEX(AW$18:AW$1048576,COUNTA(AW$18:AW$1048576))-AW$351}
A7: Since 2010 election | B7: {=INDEX(B$18:B$1048576,COUNTA(B$18:B$1048576))-B$233} | C7: {=INDEX(C$18:C$1048576,COUNTA(C$18:C$1048576))-C$233} | D7: {=INDEX(D$18:D$1048576,COUNTA(D$18:D$1048576))-D$233} | E7: {=INDEX(E$18:E$1048576,COUNTA(E$18:E$1048576))-E$233} | F7: {=INDEX(F$18:F$1048576,COUNTA(F$18:F$1048576))-F$233} | G7: {=INDEX(G$18:G$1048576,COUNTA(G$18:G$1048576))-G$233} | H7: {=INDEX(H$18:H$1048576,COUNTA(H$18:H$1048576))-H$233} | I7: {=INDEX(I$18:I$1048576,COUNTA(I$18:I$1048576))-I$233} | ... AW7: {=INDEX(AW$18:AW$1048576,COUNTA(AW$18:AW$1048576))-AW$233}
A9: Table 11: Economic inactivity for those aged from 16 to 64 (seasonally adjusted)

Sheet 13
B1: Whole Economy | E1: Private sector3 4 5 | H1: Public sector3 4 5 | K1: Services, SIC 2007 sections G-S | N1: Finance and business services, SIC 2007 sections K-N | Q1: Public sector excluding financial services 4 5 | T1: Manufacturing, SIC 2007 section C | W1: Construction, SIC 2007 section F | Z1: Wholesaling, retailing, hotels & restaurants, SIC 2007 sections G & I
B2: Weekly Earnings (£) | C2: % changes year on year | E2: Weekly Earnings (£) | F2: % changes year on year | H2: Weekly Earnings (£) | I2: % changes year on year | K2: Weekly Earnings (£) | L2: % changes year on year | N2: Weekly Earnings (£) | O2: % changes year on year | Q2: Weekly Earnings (£) | R2: % changes year on year | T2: Weekly Earnings (£) | U2: % changes year on year | W2: Weekly Earnings (£) | X2: % changes year on year | Z2: Weekly Earnings (£) | AA2: % changes year on year
C3: Single month | D3: 3 month average 2 | F3: Single month | G3: 3 month average 2 | I3: Single month | J3: 3 month average 2 | L3: Single month | M3: 3 month average 2 | O3: Single month | P3: 3 month average 2 | R3: Single month | S3: 3 month average 2 | U3: Single month | V3: 3 month average 2 | X3: Single month | Y3: 3 month average 2 | AA3: Single month | AB3: 3 month average 2
A4: Current (3mo avg) | B4: =(AVERAGE(OFFSET(INDEX(B$18:B$1048576,COUNTA(B$18:B$1048576)),-2,0,3,1))) | C4: {=INDEX(C$30:C$1048576,COUNTA(C$30:C$1048576))} | D4: {=INDEX(D$32:D$1048576,COUNTA(D$32:D$1048576))} | E4: =(AVERAGE(OFFSET(INDEX(E$18:E$1048576,COUNTA(E$18:E$1048576)),-2,0,3,1))) | F4: {=INDEX(F$30:F$1048576,COUNTA(F$30:F$1048576))} | G4: {=INDEX(G$32:G$1048576,COUNTA(G$32:G$1048576))} | H4: =(AVERAGE(OFFSET(INDEX(H$18:H$1048576,COUNTA(H$18:H$1048576)),-2,0,3,1))) | I4: {=INDEX(I$30:I$1048576,COUNTA(I$30:I$1048576))} | J4: {=INDEX(J$32:J$1048576,COUNTA(J$32:J$1048576))} | K4: =(AVERAGE(OFFSET(INDEX(K$18:K$1048576,COUNTA(K$18:K$1048576)),-2,0,3,1))) | L4: {=INDEX(L$30:L$1048576,COUNTA(L$30:L$1048576))} | M4: {=INDEX(M$32:M$1048576,COUNTA(M$32:M$1048576))} | N4: =(AVERAGE(OFFSET(INDEX(N$18:N$1048576,COUNTA(N$18:N$1048576)),-2,0,3,1))) | O4: {=INDEX(O$30:O$1048576,COUNTA(O$30:O$1048576))} | P4: {=INDEX(P$32:P$1048576,COUNTA(P$32:P$1048576))} | Q4: =(AVERAGE(OFFSET(INDEX(Q$18:Q$1048576,COUNTA(Q$18:Q$1048576)),-2,0,3,1))) | R4: {=INDEX(R$30:R$1048576,COUNTA(R$30:R$1048576))} | S4: {=INDEX(S$32:S$1048576,COUNTA(S$32:S$1048576))} | T4: =(AVERAGE(OFFSET(INDEX(T$18:T$1048576,COUNTA(T$18:T$1048576)),-2,0,3,1))) | U4: {=INDEX(U$30:U$1048576,COUNTA(U$30:U$1048576))} | V4: {=INDEX(V$32:V$1048576,COUNTA(V$32:V$1048576))} | W4: =(AVERAGE(OFFSET(INDEX(W$18:W$1048576,COUNTA(W$18:W$1048576)),-2,0,3,1))) | X4: {=INDEX(X$30:X$1048576,COUNTA(X$30:X$1048576))} | Y4: {=INDEX(Y$32:Y$1048576,COUNTA(Y$32:Y$1048576))} | Z4: =(AVERAGE(OFFSET(INDEX(Z$18:Z$1048576,COUNTA(Z$18:Z$1048576)),-2,0,3,1))) | AA4: {=INDEX(AA$30:AA$1048576,COUNTA(AA$30:AA$1048576))} | AB4: {=INDEX(AB$32:AB$1048576,COUNTA(AB$32:AB$1048576))}
A5: Change on quarter | B5: =(AVERAGE(OFFSET(INDEX(B$18:B$1048576,COUNTA(B$18:B$1048576)),-2,0,3,1))-AVERAGE(OFFSET(INDEX(B$18:B$1048576,COUNTA(B$18:B$1048576)),-5,0,3,1)))*52 | C5: {=INDEX(C$30:C$1048576,COUNTA(C$30:C$1048576))-INDEX(C$30:C$1048576,COUNTA(C$30:C$1048576)-3)} | D5: {=INDEX(D$32:D$1048576,COUNTA(D$32:D$1048576))-INDEX(D$32:D$1048576,COUNTA(D$32:D$1048576)-3)} | E5: =(AVERAGE(OFFSET(INDEX(E$18:E$1048576,COUNTA(E$18:E$1048576)),-2,0,3,1))-AVERAGE(OFFSET(INDEX(E$18:E$1048576,COUNTA(E$18:E$1048576)),-5,0,3,1)))*52 | F5: {=INDEX(F$30:F$1048576,COUNTA(F$30:F$1048576))-INDEX(F$30:F$1048576,COUNTA(F$30:F$1048576)-3)} | G5: {=INDEX(G$32:G$1048576,COUNTA(G$32:G$1048576))-INDEX(G$32:G$1048576,COUNTA(G$32:G$1048576)-3)} | H5: =(AVERAGE(OFFSET(INDEX(H$18:H$1048576,COUNTA(H$18:H$1048576)),-2,0,3,1))-AVERAGE(OFFSET(INDEX(H$18:H$1048576,COUNTA(H$18:H$1048576)),-5,0,3,1)))*52 | I5: {=INDEX(I$30:I$1048576,COUNTA(I$30:I$1048576))-INDEX(I$30:I$1048576,COUNTA(I$30:I$1048576)-3)} | J5: {=INDEX(J$32:J$1048576,COUNTA(J$32:J$1048576))-INDEX(J$32:J$1048576,COUNTA(J$32:J$1048576)-3)} | K5: =(AVERAGE(OFFSET(INDEX(K$18:K$1048576,COUNTA(K$18:K$1048576)),-2,0,3,1))-AVERAGE(OFFSET(INDEX(K$18:K$1048576,COUNTA(K$18:K$1048576)),-5,0,3,1)))*52 | L5: {=INDEX(L$30:L$1048576,COUNTA(L$30:L$1048576))-INDEX(L$30:L$1048576,COUNTA(L$30:L$1048576)-3)} | M5: {=INDEX(M$32:M$1048576,COUNTA(M$32:M$1048576))-INDEX(M$32:M$1048576,COUNTA(M$32:M$1048576)-3)} | N5: =(AVERAGE(OFFSET(INDEX(N$18:N$1048576,COUNTA(N$18:N$1048576)),-2,0,3,1))-AVERAGE(OFFSET(INDEX(N$18:N$1048576,COUNTA(N$18:N$1048576)),-5,0,3,1)))*52 | O5: {=INDEX(O$30:O$1048576,COUNTA(O$30:O$1048576))-INDEX(O$30:O$1048576,COUNTA(O$30:O$1048576)-3)} | P5: {=INDEX(P$32:P$1048576,COUNTA(P$32:P$1048576))-INDEX(P$32:P$1048576,COUNTA(P$32:P$1048576)-3)} | Q5: =(AVERAGE(OFFSET(INDEX(Q$18:Q$1048576,COUNTA(Q$18:Q$1048576)),-2,0,3,1))-AVERAGE(OFFSET(INDEX(Q$18:Q$1048576,COUNTA(Q$18:Q$1048576)),-5,0,3,1)))*52 | R5: {=INDEX(R$30:R$1048576,COUNTA(R$30:R$1048576))-INDEX(R$30:R$1048576,COUNTA(R$30:R$1048576)-3)} | S5: {=INDEX(S$32:S$1048576,COUNTA(S$32:S$1048576))-INDEX(S$32:S$1048576,COUNTA(S$32:S$1048576)-3)} | T5: =(AVERAGE(OFFSET(INDEX(T$18:T$1048576,COUNTA(T$18:T$1048576)),-2,0,3,1))-AVERAGE(OFFSET(INDEX(T$18:T$1048576,COUNTA(T$18:T$1048576)),-5,0,3,1)))*52 | U5: {=INDEX(U$30:U$1048576,COUNTA(U$30:U$1048576))-INDEX(U$30:U$1048576,COUNTA(U$30:U$1048576)-3)} | V5: {=INDEX(V$32:V$1048576,COUNTA(V$32:V$1048576))-INDEX(V$32:V$1048576,COUNTA(V$32:V$1048576)-3)} | W5: =(AVERAGE(OFFSET(INDEX(W$18:W$1048576,COUNTA(W$18:W$1048576)),-2,0,3,1))-AVERAGE(OFFSET(INDEX(W$18:W$1048576,COUNTA(W$18:W$1048576)),-5,0,3,1)))*52 | X5: {=INDEX(X$30:X$1048576,COUNTA(X$30:X$1048576))-INDEX(X$30:X$1048576,COUNTA(X$30:X$1048576)-3)} | Y5: {=INDEX(Y$32:Y$1048576,COUNTA(Y$32:Y$1048576))-INDEX(Y$32:Y$1048576,COUNTA(Y$32:Y$1048576)-3)} | Z5: =(AVERAGE(OFFSET(INDEX(Z$18:Z$1048576,COUNTA(Z$18:Z$1048576)),-2,0,3,1))-AVERAGE(OFFSET(INDEX(Z$18:Z$1048576,COUNTA(Z$18:Z$1048576)),-5,0,3,1)))*52 | AA5: {=INDEX(AA$30:AA$1048576,COUNTA(AA$30:AA$1048576))-INDEX(AA$30:AA$1048576,COUNTA(AA$30:AA$1048576)-3)} | AB5: {=INDEX(AB$32:AB$1048576,COUNTA(AB$32:AB$1048576))-INDEX(AB$32:AB$1048576,COUNTA(AB$32:AB$1048576)-3)}
A6: Change year on year | B6: =(AVERAGE(OFFSET(INDEX(B$18:B$1048576,COUNTA(B$18:B$1048576)),-2,0,3,1))-AVERAGE(OFFSET(INDEX(B$18:B$1048576,COUNTA(B$18:B$1048576)),-14,0,3,1)))*52 | C6: {=INDEX(C$30:C$1048576,COUNTA(C$30:C$1048576))-INDEX(C$30:C$1048576,COUNTA(C$30:C$1048576)-12)} | D6: {=INDEX(D$32:D$1048576,COUNTA(D$32:D$1048576))-INDEX(D$32:D$1048576,COUNTA(D$32:D$1048576)-12)} | E6: =(AVERAGE(OFFSET(INDEX(E$18:E$1048576,COUNTA(E$18:E$1048576)),-2,0,3,1))-AVERAGE(OFFSET(INDEX(E$18:E$1048576,COUNTA(E$18:E$1048576)),-14,0,3,1)))*52 | F6: {=INDEX(F$30:F$1048576,COUNTA(F$30:F$1048576))-INDEX(F$30:F$1048576,COUNTA(F$30:F$1048576)-12)} | G6: {=INDEX(G$32:G$1048576,COUNTA(G$32:G$1048576))-INDEX(G$32:G$1048576,COUNTA(G$32:G$1048576)-12)} | H6: =(AVERAGE(OFFSET(INDEX(H$18:H$1048576,COUNTA(H$18:H$1048576)),-2,0,3,1))-AVERAGE(OFFSET(INDEX(H$18:H$1048576,COUNTA(H$18:H$1048576)),-14,0,3,1)))*52 | I6: {=INDEX(I$30:I$1048576,COUNTA(I$30:I$1048576))-INDEX(I$30:I$1048576,COUNTA(I$30:I$1048576)-12)} | J6: {=INDEX(J$32:J$1048576,COUNTA(J$32:J$1048576))-INDEX(J$32:J$1048576,COUNTA(J$32:J$1048576)-12)} | K6: =(AVERAGE(OFFSET(INDEX(K$18:K$1048576,COUNTA(K$18:K$1048576)),-2,0,3,1))-AVERAGE(OFFSET(INDEX(K$18:K$1048576,COUNTA(K$18:K$1048576)),-14,0,3,1)))*52 | L6: {=INDEX(L$30:L$1048576,COUNTA(L$30:L$1048576))-INDEX(L$30:L$1048576,COUNTA(L$30:L$1048576)-12)} | M6: {=INDEX(M$32:M$1048576,COUNTA(M$32:M$1048576))-INDEX(M$32:M$1048576,COUNTA(M$32:M$1048576)-12)} | N6: =(AVERAGE(OFFSET(INDEX(N$18:N$1048576,COUNTA(N$18:N$1048576)),-2,0,3,1))-AVERAGE(OFFSET(INDEX(N$18:N$1048576,COUNTA(N$18:N$1048576)),-14,0,3,1)))*52 | O6: {=INDEX(O$30:O$1048576,COUNTA(O$30:O$1048576))-INDEX(O$30:O$1048576,COUNTA(O$30:O$1048576)-12)} | P6: {=INDEX(P$32:P$1048576,COUNTA(P$32:P$1048576))-INDEX(P$32:P$1048576,COUNTA(P$32:P$1048576)-12)} | Q6: =(AVERAGE(OFFSET(INDEX(Q$18:Q$1048576,COUNTA(Q$18:Q$1048576)),-2,0,3,1))-AVERAGE(OFFSET(INDEX(Q$18:Q$1048576,COUNTA(Q$18:Q$1048576)),-14,0,3,1)))*52 | R6: {=INDEX(R$30:R$1048576,COUNTA(R$30:R$1048576))-INDEX(R$30:R$1048576,COUNTA(R$30:R$1048576)-12)} | S6: {=INDEX(S$32:S$1048576,COUNTA(S$32:S$1048576))-INDEX(S$32:S$1048576,COUNTA(S$32:S$1048576)-12)} | T6: =(AVERAGE(OFFSET(INDEX(T$18:T$1048576,COUNTA(T$18:T$1048576)),-2,0,3,1))-AVERAGE(OFFSET(INDEX(T$18:T$1048576,COUNTA(T$18:T$1048576)),-14,0,3,1)))*52 | U6: {=INDEX(U$30:U$1048576,COUNTA(U$30:U$1048576))-INDEX(U$30:U$1048576,COUNTA(U$30:U$1048576)-12)} | V6: {=INDEX(V$32:V$1048576,COUNTA(V$32:V$1048576))-INDEX(V$32:V$1048576,COUNTA(V$32:V$1048576)-12)} | W6: =(AVERAGE(OFFSET(INDEX(W$18:W$1048576,COUNTA(W$18:W$1048576)),-2,0,3,1))-AVERAGE(OFFSET(INDEX(W$18:W$1048576,COUNTA(W$18:W$1048576)),-14,0,3,1)))*52 | X6: {=INDEX(X$30:X$1048576,COUNTA(X$30:X$1048576))-INDEX(X$30:X$1048576,COUNTA(X$30:X$1048576)-12)} | Y6: {=INDEX(Y$32:Y$1048576,COUNTA(Y$32:Y$1048576))-INDEX(Y$32:Y$1048576,COUNTA(Y$32:Y$1048576)-12)} | Z6: =(AVERAGE(OFFSET(INDEX(Z$18:Z$1048576,COUNTA(Z$18:Z$1048576)),-2,0,3,1))-AVERAGE(OFFSET(INDEX(Z$18:Z$1048576,COUNTA(Z$18:Z$1048576)),-14,0,3,1)))*52 | AA6: {=INDEX(AA$30:AA$1048576,COUNTA(AA$30:AA$1048576))-INDEX(AA$30:AA$1048576,COUNTA(AA$30:AA$1048576)-12)} | AB6: {=INDEX(AB$32:AB$1048576,COUNTA(AB$32:AB$1048576))-INDEX(AB$32:AB$1048576,COUNTA(AB$32:AB$1048576)-12)}
A7: Change since Covid-19 | B7: =(AVERAGE(OFFSET(INDEX(B$18:B$1048576,COUNTA(B$18:B$1048576)),-2,0,3,1))-AVERAGE($B$257:$B$259))*52 | C7: {=INDEX(C$30:C$1048576,COUNTA(C$30:C$1048576))-AVERAGE($C$257:$C$259)} | D7: {=INDEX(D$32:D$1048576,COUNTA(D$32:D$1048576))-AVERAGE($D$257:$D$259)} | E7: =(AVERAGE(OFFSET(INDEX(E$18:E$1048576,COUNTA(E$18:E$1048576)),-2,0,3,1))-AVERAGE($B$257:$B$259))*52 | F7: {=INDEX(F$30:F$1048576,COUNTA(F$30:F$1048576))-AVERAGE($C$257:$C$259)} | G7: {=INDEX(G$32:G$1048576,COUNTA(G$32:G$1048576))-AVERAGE($D$257:$D$259)} | H7: =(AVERAGE(OFFSET(INDEX(H$18:H$1048576,COUNTA(H$18:H$1048576)),-2,0,3,1))-AVERAGE($B$257:$B$259))*52 | I7: {=INDEX(I$30:I$1048576,COUNTA(I$30:I$1048576))-AVERAGE($C$257:$C$259)} | J7: {=INDEX(J$32:J$1048576,COUNTA(J$32:J$1048576))-AVERAGE($D$257:$D$259)} | K7: =(AVERAGE(OFFSET(INDEX(K$18:K$1048576,COUNTA(K$18:K$1048576)),-2,0,3,1))-AVERAGE($B$257:$B$259))*52 | L7: {=INDEX(L$30:L$1048576,COUNTA(L$30:L$1048576))-AVERAGE($C$257:$C$259)} | M7: {=INDEX(M$32:M$1048576,COUNTA(M$32:M$1048576))-AVERAGE($D$257:$D$259)} | N7: =(AVERAGE(OFFSET(INDEX(N$18:N$1048576,COUNTA(N$18:N$1048576)),-2,0,3,1))-AVERAGE($B$257:$B$259))*52 | O7: {=INDEX(O$30:O$1048576,COUNTA(O$30:O$1048576))-AVERAGE($C$257:$C$259)} | P7: {=INDEX(P$32:P$1048576,COUNTA(P$32:P$1048576))-AVERAGE($D$257:$D$259)} | Q7: =(AVERAGE(OFFSET(INDEX(Q$18:Q$1048576,COUNTA(Q$18:Q$1048576)),-2,0,3,1))-AVERAGE($B$257:$B$259))*52 | R7: {=INDEX(R$30:R$1048576,COUNTA(R$30:R$1048576))-AVERAGE($C$257:$C$259)} | S7: {=INDEX(S$32:S$1048576,COUNTA(S$32:S$1048576))-AVERAGE($D$257:$D$259)} | T7: =(AVERAGE(OFFSET(INDEX(T$18:T$1048576,COUNTA(T$18:T$1048576)),-2,0,3,1))-AVERAGE($B$257:$B$259))*52 | U7: {=INDEX(U$30:U$1048576,COUNTA(U$30:U$1048576))-AVERAGE($C$257:$C$259)} | V7: {=INDEX(V$32:V$1048576,COUNTA(V$32:V$1048576))-AVERAGE($D$257:$D$259)} | W7: =(AVERAGE(OFFSET(INDEX(W$18:W$1048576,COUNTA(W$18:W$1048576)),-2,0,3,1))-AVERAGE($B$257:$B$259))*52 | X7: {=INDEX(X$30:X$1048576,COUNTA(X$30:X$1048576))-AVERAGE($C$257:$C$259)} | Y7: {=INDEX(Y$32:Y$1048576,COUNTA(Y$32:Y$1048576))-AVERAGE($D$257:$D$259)} | Z7: =(AVERAGE(OFFSET(INDEX(Z$18:Z$1048576,COUNTA(Z$18:Z$1048576)),-2,0,3,1))-AVERAGE($B$257:$B$259))*52 | AA7: {=INDEX(AA$30:AA$1048576,COUNTA(AA$30:AA$1048576))-AVERAGE($C$257:$C$259)} | AB7: {=INDEX(AB$32:AB$1048576,COUNTA(AB$32:AB$1048576))-AVERAGE($D$257:$D$259)}
A9: Table 13: Average Weekly Earnings (nominal) - Total Pay (Great Britain, seasonally adjusted)1 | M9: Source: Monthly Wages & Salaries Survey
A10: Date of publication: | E10: 45643 | H10: Date of next publication: | L10: 45678
A11: Inquiries: Email: | C11: labour.market@ons.gov.uk | J11: Tel: 01633 455400
A12: Standard Industrial Classification (2007)
B13: Whole Economy | E13: Private sector3 4 5 | H13: Public sector3 4 5 | K13: Services, SIC 2007 sections G-S | N13: Finance and business services, SIC 2007 sections K-N | Q13: Public sector excluding financial services 4 5 | T13: Manufacturing, SIC 2007 section C | W13: Construction, SIC 2007 section F | Z13: Wholesaling, retailing, hotels & restaurants, SIC 2007 sections G & I
B14: Weekly Earnings (£) | C14: % changes year on year | E14: Weekly Earnings (£) | F14: % changes year on year | H14: Weekly Earnings (£) | I14: % changes year on year | K14: Weekly Earnings (£) | L14: % changes year on year | N14: Weekly Earnings (£) | O14: % changes year on year | Q14: Weekly Earnings (£) | R14: % changes year on year | T14: Weekly Earnings (£) | U14: % changes year on year | W14: Weekly Earnings (£) | X14: % changes year on year | Z14: Weekly Earnings (£) | AA14: % changes year on year
C15: Single month | D15: 3 month average 2 | F15: Single month | G15: 3 month average 2 | I15: Single month | J15: 3 month average 2 | L15: Single month | M15: 3 month average 2 | O15: Single month | P15: 3 month average 2 | R15: Single month | S15: 3 month average 2 | U15: Single month | V15: 3 month average 2 | X15: Single month | Y15: 3 month average 2 | AA15: Single month | AB15: 3 month average 2
B16: KAB9 | C16: KAC2 | D16: KAC3 | E16: KAC4 | F16: KAC5 | G16: KAC6 | H16: KAC7 | I16: KAC8 | J16: KAC9 | K16: K5BZ | L16: K5C2 | M16: K5C3 | N16: K5C4 | O16: K5C5 | P16: K5C6 | Q16: KAD8 | R16: KAD9 | S16: KAE2 | T16: K5CA | U16: K5CB | V16: K5CC | W16: K5CD | X16: K5CE | Y16: K5CF | Z16: K5CG | AA16: K5CH | AB16: K5CI

Sheet 15
B1: Whole Economy | E1: Private sector 3 4 5 | H1: Public sector 3 4 5 | K1: Services, SIC 2007 sections G-S | N1: Finance and business services, SIC 2007 sections K-N | Q1: Public sector excluding financial services 4 5 | T1: Manufacturing, SIC 2007 section C | W1: Construction, SIC 2007 section F | Z1: Wholesaling, retailing, hotels & restaurants, SIC 2007 sections G & I
B2: Weekly Earnings (£) | C2: % changes year on year | E2: Weekly Earnings (£) | F2: % changes year on year | H2: Weekly Earnings (£) | I2: % changes year on year | K2: Weekly Earnings (£) | L2: % changes year on year | N2: Weekly Earnings (£) | O2: % changes year on year | Q2: Weekly Earnings (£) | R2: % changes year on year | T2: Weekly Earnings (£) | U2: % changes year on year | W2: Weekly Earnings (£) | X2: % changes year on year | Z2: Weekly Earnings (£) | AA2: % changes year on year
C3: Single month | D3: 3 month average 2 | F3: Single month | G3: 3 month average 2 | I3: Single month | J3: 3 month average 2 | L3: Single month | M3: 3 month average 2 | O3: Single month | P3: 3 month average 2 | R3: Single month | S3: 3 month average 2 | U3: Single month | V3: 3 month average 2 | X3: Single month | Y3: 3 month average 2 | AA3: Single month | AB3: 3 month average 2
A4: Current | B4: {=INDEX(B$19:B$1048576,COUNTA(B$19:B$1048576))} | C4: {=INDEX(C$31:C$1048576,COUNTA(C$31:C$1048576))} | D4: {=INDEX(D$33:D$1048576,COUNTA(D$33:D$1048576))} | E4: {=INDEX(E$19:E$1048576,COUNTA(E$19:E$1048576))} | F4: {=INDEX(F$31:F$1048576,COUNTA(F$31:F$1048576))} | G4: {=INDEX(G$33:G$1048576,COUNTA(G$33:G$1048576))} | H4: {=INDEX(H$19:H$1048576,COUNTA(H$19:H$1048576))} | I4: {=INDEX(I$31:I$1048576,COUNTA(I$31:I$1048576))} | J4: {=INDEX(J$33:J$1048576,COUNTA(J$33:J$1048576))} | K4: {=INDEX(K$19:K$1048576,COUNTA(K$19:K$1048576))} | L4: {=INDEX(L$31:L$1048576,COUNTA(L$31:L$1048576))} | M4: {=INDEX(M$33:M$1048576,COUNTA(M$33:M$1048576))} | N4: {=INDEX(N$19:N$1048576,COUNTA(N$19:N$1048576))} | O4: {=INDEX(O$31:O$1048576,COUNTA(O$31:O$1048576))} | P4: {=INDEX(P$33:P$1048576,COUNTA(P$33:P$1048576))} | Q4: {=INDEX(Q$19:Q$1048576,COUNTA(Q$19:Q$1048576))} | R4: {=INDEX(R$31:R$1048576,COUNTA(R$31:R$1048576))} | S4: {=INDEX(S$33:S$1048576,COUNTA(S$33:S$1048576))} | T4: {=INDEX(T$19:T$1048576,COUNTA(T$19:T$1048576))} | U4: {=INDEX(U$31:U$1048576,COUNTA(U$31:U$1048576))} | V4: {=INDEX(V$33:V$1048576,COUNTA(V$33:V$1048576))} | W4: {=INDEX(W$19:W$1048576,COUNTA(W$19:W$1048576))} | X4: {=INDEX(X$31:X$1048576,COUNTA(X$31:X$1048576))} | Y4: {=INDEX(Y$33:Y$1048576,COUNTA(Y$33:Y$1048576))} | Z4: {=INDEX(Z$19:Z$1048576,COUNTA(Z$19:Z$1048576))} | AA4: {=INDEX(AA$31:AA$1048576,COUNTA(AA$31:AA$1048576))} | AB4: {=INDEX(AB$33:AB$1048576,COUNTA(AB$33:AB$1048576))}
A5: Quarterly change | B5: {=INDEX(B$19:B$1048576,COUNTA(B$19:B$1048576))-INDEX(B$19:B$1048576,COUNTA(B$19:B$1048576)-3)} | C5: {=INDEX(C$31:C$1048576,COUNTA(C$31:C$1048576))-INDEX(C$31:C$1048576,COUNTA(C$31:C$1048576)-3)} | D5: {=INDEX(D$33:D$1048576,COUNTA(D$33:D$1048576))-INDEX(D$33:D$1048576,COUNTA(D$33:D$1048576)-3)} | E5: {=INDEX(E$19:E$1048576,COUNTA(E$19:E$1048576))-INDEX(E$19:E$1048576,COUNTA(E$19:E$1048576)-3)} | F5: {=INDEX(F$31:F$1048576,COUNTA(F$31:F$1048576))-INDEX(F$31:F$1048576,COUNTA(F$31:F$1048576)-3)} | G5: {=INDEX(G$33:G$1048576,COUNTA(G$33:G$1048576))-INDEX(G$33:G$1048576,COUNTA(G$33:G$1048576)-3)} | H5: {=INDEX(H$19:H$1048576,COUNTA(H$19:H$1048576))-INDEX(H$19:H$1048576,COUNTA(H$19:H$1048576)-3)} | I5: {=INDEX(I$31:I$1048576,COUNTA(I$31:I$1048576))-INDEX(I$31:I$1048576,COUNTA(I$31:I$1048576)-3)} | J5: {=INDEX(J$33:J$1048576,COUNTA(J$33:J$1048576))-INDEX(J$33:J$1048576,COUNTA(J$33:J$1048576)-3)} | K5: {=INDEX(K$19:K$1048576,COUNTA(K$19:K$1048576))-INDEX(K$19:K$1048576,COUNTA(K$19:K$1048576)-3)} | L5: {=INDEX(L$31:L$1048576,COUNTA(L$31:L$1048576))-INDEX(L$31:L$1048576,COUNTA(L$31:L$1048576)-3)} | M5: {=INDEX(M$33:M$1048576,COUNTA(M$33:M$1048576))-INDEX(M$33:M$1048576,COUNTA(M$33:M$1048576)-3)} | N5: {=INDEX(N$19:N$1048576,COUNTA(N$19:N$1048576))-INDEX(N$19:N$1048576,COUNTA(N$19:N$1048576)-3)} | O5: {=INDEX(O$31:O$1048576,COUNTA(O$31:O$1048576))-INDEX(O$31:O$1048576,COUNTA(O$31:O$1048576)-3)} | P5: {=INDEX(P$33:P$1048576,COUNTA(P$33:P$1048576))-INDEX(P$33:P$1048576,COUNTA(P$33:P$1048576)-3)} | Q5: {=INDEX(Q$19:Q$1048576,COUNTA(Q$19:Q$1048576))-INDEX(Q$19:Q$1048576,COUNTA(Q$19:Q$1048576)-3)} | R5: {=INDEX(R$31:R$1048576,COUNTA(R$31:R$1048576))-INDEX(R$31:R$1048576,COUNTA(R$31:R$1048576)-3)} | S5: {=INDEX(S$33:S$1048576,COUNTA(S$33:S$1048576))-INDEX(S$33:S$1048576,COUNTA(S$33:S$1048576)-3)} | T5: {=INDEX(T$19:T$1048576,COUNTA(T$19:T$1048576))-INDEX(T$19:T$1048576,COUNTA(T$19:T$1048576)-3)} | U5: {=INDEX(U$31:U$1048576,COUNTA(U$31:U$1048576))-INDEX(U$31:U$1048576,COUNTA(U$31:U$1048576)-3)} | V5: {=INDEX(V$33:V$1048576,COUNTA(V$33:V$1048576))-INDEX(V$33:V$1048576,COUNTA(V$33:V$1048576)-3)} | W5: {=INDEX(W$19:W$1048576,COUNTA(W$19:W$1048576))-INDEX(W$19:W$1048576,COUNTA(W$19:W$1048576)-3)} | X5: {=INDEX(X$31:X$1048576,COUNTA(X$31:X$1048576))-INDEX(X$31:X$1048576,COUNTA(X$31:X$1048576)-3)} | Y5: {=INDEX(Y$33:Y$1048576,COUNTA(Y$33:Y$1048576))-INDEX(Y$33:Y$1048576,COUNTA(Y$33:Y$1048576)-3)} | Z5: {=INDEX(Z$19:Z$1048576,COUNTA(Z$19:Z$1048576))-INDEX(Z$19:Z$1048576,COUNTA(Z$19:Z$1048576)-3)} | AA5: {=INDEX(AA$31:AA$1048576,COUNTA(AA$31:AA$1048576))-INDEX(AA$31:AA$1048576,COUNTA(AA$31:AA$1048576)-3)} | AB5: {=INDEX(AB$33:AB$1048576,COUNTA(AB$33:AB$1048576))-INDEX(AB$33:AB$1048576,COUNTA(AB$33:AB$1048576)-3)}
A6: year on year change | B6: {=INDEX(B$19:B$1048576,COUNTA(B$19:B$1048576))-INDEX(B$19:B$1048576,COUNTA(B$19:B$1048576)-12)} | C6: {=INDEX(C$31:C$1048576,COUNTA(C$31:C$1048576))-INDEX(C$31:C$1048576,COUNTA(C$31:C$1048576)-12)} | D6: {=INDEX(D$33:D$1048576,COUNTA(D$33:D$1048576))-INDEX(D$33:D$1048576,COUNTA(D$33:D$1048576)-12)} | E6: {=INDEX(E$19:E$1048576,COUNTA(E$19:E$1048576))-INDEX(E$19:E$1048576,COUNTA(E$19:E$1048576)-12)} | F6: {=INDEX(F$31:F$1048576,COUNTA(F$31:F$1048576))-INDEX(F$31:F$1048576,COUNTA(F$31:F$1048576)-12)} | G6: {=INDEX(G$33:G$1048576,COUNTA(G$33:G$1048576))-INDEX(G$33:G$1048576,COUNTA(G$33:G$1048576)-12)} | H6: {=INDEX(H$19:H$1048576,COUNTA(H$19:H$1048576))-INDEX(H$19:H$1048576,COUNTA(H$19:H$1048576)-12)} | I6: {=INDEX(I$31:I$1048576,COUNTA(I$31:I$1048576))-INDEX(I$31:I$1048576,COUNTA(I$31:I$1048576)-12)} | J6: {=INDEX(J$33:J$1048576,COUNTA(J$33:J$1048576))-INDEX(J$33:J$1048576,COUNTA(J$33:J$1048576)-12)} | K6: {=INDEX(K$19:K$1048576,COUNTA(K$19:K$1048576))-INDEX(K$19:K$1048576,COUNTA(K$19:K$1048576)-12)} | L6: {=INDEX(L$31:L$1048576,COUNTA(L$31:L$1048576))-INDEX(L$31:L$1048576,COUNTA(L$31:L$1048576)-12)} | M6: {=INDEX(M$33:M$1048576,COUNTA(M$33:M$1048576))-INDEX(M$33:M$1048576,COUNTA(M$33:M$1048576)-12)} | N6: {=INDEX(N$19:N$1048576,COUNTA(N$19:N$1048576))-INDEX(N$19:N$1048576,COUNTA(N$19:N$1048576)-12)} | O6: {=INDEX(O$31:O$1048576,COUNTA(O$31:O$1048576))-INDEX(O$31:O$1048576,COUNTA(O$31:O$1048576)-12)} | P6: {=INDEX(P$33:P$1048576,COUNTA(P$33:P$1048576))-INDEX(P$33:P$1048576,COUNTA(P$33:P$1048576)-12)} | Q6: {=INDEX(Q$19:Q$1048576,COUNTA(Q$19:Q$1048576))-INDEX(Q$19:Q$1048576,COUNTA(Q$19:Q$1048576)-12)} | R6: {=INDEX(R$31:R$1048576,COUNTA(R$31:R$1048576))-INDEX(R$31:R$1048576,COUNTA(R$31:R$1048576)-12)} | S6: {=INDEX(S$33:S$1048576,COUNTA(S$33:S$1048576))-INDEX(S$33:S$1048576,COUNTA(S$33:S$1048576)-12)} | T6: {=INDEX(T$19:T$1048576,COUNTA(T$19:T$1048576))-INDEX(T$19:T$1048576,COUNTA(T$19:T$1048576)-12)} | U6: {=INDEX(U$31:U$1048576,COUNTA(U$31:U$1048576))-INDEX(U$31:U$1048576,COUNTA(U$31:U$1048576)-12)} | V6: {=INDEX(V$33:V$1048576,COUNTA(V$33:V$1048576))-INDEX(V$33:V$1048576,COUNTA(V$33:V$1048576)-12)} | W6: {=INDEX(W$19:W$1048576,COUNTA(W$19:W$1048576))-INDEX(W$19:W$1048576,COUNTA(W$19:W$1048576)-12)} | X6: {=INDEX(X$31:X$1048576,COUNTA(X$31:X$1048576))-INDEX(X$31:X$1048576,COUNTA(X$31:X$1048576)-12)} | Y6: {=INDEX(Y$33:Y$1048576,COUNTA(Y$33:Y$1048576))-INDEX(Y$33:Y$1048576,COUNTA(Y$33:Y$1048576)-12)} | Z6: {=INDEX(Z$19:Z$1048576,COUNTA(Z$19:Z$1048576))-INDEX(Z$19:Z$1048576,COUNTA(Z$19:Z$1048576)-12)} | AA6: {=INDEX(AA$31:AA$1048576,COUNTA(AA$31:AA$1048576))-INDEX(AA$31:AA$1048576,COUNTA(AA$31:AA$1048576)-12)} | AB6: {=INDEX(AB$33:AB$1048576,COUNTA(AB$33:AB$1048576))-INDEX(AB$33:AB$1048576,COUNTA(AB$33:AB$1048576)-12)}
A7: Since pandemic | B7: {=INDEX(B$19:B$1048576,COUNTA(B$19:B$1048576))-B$260} | C7: {=INDEX(C$31:C$1048576,COUNTA(C$31:C$1048576))-C$260} | D7: {=INDEX(D$31:D$1048576,COUNTA(D$31:D$1048576))-D$260} | E7: {=INDEX(E$19:E$1048576,COUNTA(E$19:E$1048576))-E$260} | F7: {=INDEX(F$31:F$1048576,COUNTA(F$31:F$1048576))-F$260} | G7: {=INDEX(G$31:G$1048576,COUNTA(G$31:G$1048576))-G$260} | H7: {=INDEX(H$19:H$1048576,COUNTA(H$19:H$1048576))-H$260} | I7: {=INDEX(I$31:I$1048576,COUNTA(I$31:I$1048576))-I$260} | J7: {=INDEX(J$31:J$1048576,COUNTA(J$31:J$1048576))-J$260} | K7: {=INDEX(K$19:K$1048576,COUNTA(K$19:K$1048576))-K$260} | L7: {=INDEX(L$31:L$1048576,COUNTA(L$31:L$1048576))-L$260} | M7: {=INDEX(M$31:M$1048576,COUNTA(M$31:M$1048576))-M$260} | N7: {=INDEX(N$19:N$1048576,COUNTA(N$19:N$1048576))-N$260} | O7: {=INDEX(O$31:O$1048576,COUNTA(O$31:O$1048576))-O$260} | P7: {=INDEX(P$31:P$1048576,COUNTA(P$31:P$1048576))-P$260} | Q7: {=INDEX(Q$19:Q$1048576,COUNTA(Q$19:Q$1048576))-Q$260} | R7: {=INDEX(R$31:R$1048576,COUNTA(R$31:R$1048576))-R$260} | S7: {=INDEX(S$31:S$1048576,COUNTA(S$31:S$1048576))-S$260} | T7: {=INDEX(T$19:T$1048576,COUNTA(T$19:T$1048576))-T$260} | U7: {=INDEX(U$31:U$1048576,COUNTA(U$31:U$1048576))-U$260} | V7: {=INDEX(V$31:V$1048576,COUNTA(V$31:V$1048576))-V$260} | W7: {=INDEX(W$19:W$1048576,COUNTA(W$19:W$1048576))-W$260} | X7: {=INDEX(X$31:X$1048576,COUNTA(X$31:X$1048576))-X$260} | Y7: {=INDEX(Y$31:Y$1048576,COUNTA(Y$31:Y$1048576))-Y$260} | Z7: {=INDEX(Z$19:Z$1048576,COUNTA(Z$19:Z$1048576))-Z$260} | AA7: {=INDEX(AA$31:AA$1048576,COUNTA(AA$31:AA$1048576))-AA$260} | AB7: {=INDEX(AB$31:AB$1048576,COUNTA(AB$31:AB$1048576))-AB$260}
A8: Since 2010 election | B8: {=INDEX(B$19:B$1048576,COUNTA(B$19:B$1048576))-B$142} | C8: {=INDEX(C$31:C$1048576,COUNTA(C$31:C$1048576))-C$142} | D8: {=INDEX(D$31:D$1048576,COUNTA(D$31:D$1048576))-D$142} | E8: {=INDEX(E$19:E$1048576,COUNTA(E$19:E$1048576))-E$142} | F8: {=INDEX(F$31:F$1048576,COUNTA(F$31:F$1048576))-F$142} | G8: {=INDEX(G$31:G$1048576,COUNTA(G$31:G$1048576))-G$142} | H8: {=INDEX(H$19:H$1048576,COUNTA(H$19:H$1048576))-H$142} | I8: {=INDEX(I$31:I$1048576,COUNTA(I$31:I$1048576))-I$142} | J8: {=INDEX(J$31:J$1048576,COUNTA(J$31:J$1048576))-J$142} | K8: {=INDEX(K$19:K$1048576,COUNTA(K$19:K$1048576))-K$142} | L8: {=INDEX(L$31:L$1048576,COUNTA(L$31:L$1048576))-L$142} | M8: {=INDEX(M$31:M$1048576,COUNTA(M$31:M$1048576))-M$142} | N8: {=INDEX(N$19:N$1048576,COUNTA(N$19:N$1048576))-N$142} | O8: {=INDEX(O$31:O$1048576,COUNTA(O$31:O$1048576))-O$142} | P8: {=INDEX(P$31:P$1048576,COUNTA(P$31:P$1048576))-P$142} | Q8: {=INDEX(Q$19:Q$1048576,COUNTA(Q$19:Q$1048576))-Q$142} | R8: {=INDEX(R$31:R$1048576,COUNTA(R$31:R$1048576))-R$142} | S8: {=INDEX(S$31:S$1048576,COUNTA(S$31:S$1048576))-S$142} | T8: {=INDEX(T$19:T$1048576,COUNTA(T$19:T$1048576))-T$142} | U8: {=INDEX(U$31:U$1048576,COUNTA(U$31:U$1048576))-U$142} | V8: {=INDEX(V$31:V$1048576,COUNTA(V$31:V$1048576))-V$142} | W8: {=INDEX(W$19:W$1048576,COUNTA(W$19:W$1048576))-W$142} | X8: {=INDEX(X$31:X$1048576,COUNTA(X$31:X$1048576))-X$142} | Y8: {=INDEX(Y$31:Y$1048576,COUNTA(Y$31:Y$1048576))-Y$142} | Z8: {=INDEX(Z$19:Z$1048576,COUNTA(Z$19:Z$1048576))-Z$142} | AA8: {=INDEX(AA$31:AA$1048576,COUNTA(AA$31:AA$1048576))-AA$142} | AB8: {=INDEX(AB$31:AB$1048576,COUNTA(AB$31:AB$1048576))-AB$142}
A10: Table 15: Average Weekly Earnings (nominal) - Regular Pay (Great Britain, seasonally adjusted)1 | M10: Source: Monthly Wages & Salaries Survey
A11: Date of publication: | E11: 45643 | H11: Date of next publication: | L11: 45678
A12: Inquiries: Email: | C12: labour.market@ons.gov.uk | J12: Tel: 01633 455400
A13: Standard Industrial Classification (2007)
B14: Whole Economy | E14: Private sector 3 4 5 | H14: Public sector 3 4 5 | K14: Services, SIC 2007 sections G-S | N14: Finance and business services, SIC 2007 sections K-N | Q14: Public sector excluding financial services 4 5 | T14: Manufacturing, SIC 2007 section C | W14: Construction, SIC 2007 section F | Z14: Wholesaling, retailing, hotels & restaurants, SIC 2007 sections G & I
B15: Weekly Earnings (£) | C15: % changes year on year | E15: Weekly Earnings (£) | F15: % changes year on year | H15: Weekly Earnings (£) | I15: % changes year on year | K15: Weekly Earnings (£) | L15: % changes year on year | N15: Weekly Earnings (£) | O15: % changes year on year | Q15: Weekly Earnings (£) | R15: % changes year on year | T15: Weekly Earnings (£) | U15: % changes year on year | W15: Weekly Earnings (£) | X15: % changes year on year | Z15: Weekly Earnings (£) | AA15: % changes year on year
C16: Single month | D16: 3 month average 2 | F16: Single month | G16: 3 month average 2 | I16: Single month | J16: 3 month average 2 | L16: Single month | M16: 3 month average 2 | O16: Single month | P16: 3 month average 2 | R16: Single month | S16: 3 month average 2 | U16: Single month | V16: 3 month average 2 | X16: Single month | Y16: 3 month average 2 | AA16: Single month | AB16: 3 month average 2
B17: KAI7 | C17: KAI8 | D17: KAI9 | E17: KAJ2 | F17: KAJ3 | G17: KAJ4 | H17: KAJ5 | I17: KAJ6 | J17: KAJ7 | K17: K5DL | L17: K5DM | M17: K5DN | N17: K5DO | O17: K5DP | P17: K5DQ | Q17: KAK6 | R17: KAK7 | S17: KAK8 | T17: K5DU | U17: K5DV | V17: K5DW | W17: K5DX | X17: K5DY | Y17: K5DZ | Z17: K5E2 | AA17: K5E3 | AB17: K5E4

Sheet 18
